Workbook

Sheet Lisez-moi
A1: VELA / IRIS — Plan financier : prix des lunettes et plans d'abonnement
A3: Version du 2 septembre 2026. Devise : dollars canadiens (CAD) sauf mention US$. Prix hors taxes (TPS/TVQ calculées à part).
A5: COMMENT LIRE LE CLASSEUR
A6: • Texte bleu = valeur à saisir. Fond jaune = levier clé qui change tout le modèle (taux de change, prix OEM, marge cible, prix des plans, ventes mensuelles).
A7: • Texte noir = formule. Texte vert = renvoi vers une autre feuille. Ne pas écraser les formules.
A8: • Feuille Hypothèses : toutes les entrées, avec source ou mention « hypothèse ». Feuille Coût lunettes : coût de revient par palier OEM et prix public recommandé.
A9: • Feuille Coût API par utilisateur : ce qu'un abonné coûte réellement en ElevenLabs, Gemini, OpenAI et Claude selon son usage.
A10: • Feuille Abonnements : plans GRATUIT / ESSENTIEL / PRO / ULTRA, marge par abonné, pire cas au quota, offres groupées.
A11: • Feuille Projection 12 mois : ventes, abonnés, résultat et trésorerie mois par mois, seuil de rentabilité.
A13: CE QUI EST VÉRIFIÉ (2 septembre 2026)
A14: • ElevenLabs : Free 10 000 crédits ; Starter 6 US$ / 30 000 ; Creator 22 US$ / 121 000 ; Pro 99 US$ / 600 000 ; Scale 299 US$ / 1,8 M ; Business 990 US$ / 6 M. Flash v2.5 = 0,5 crédit par caractère. (elevenlabs.io/pricing)
A15: • Gemini API : 2.5 Flash 0,30 / 2,50 US$ par M jetons ; 3.7 Flash 0,75 / 3,75 (double au 1er janvier 2027) ; 2.5 Pro 1,25 / 10. (ai.google.dev/gemini-api/docs/pricing)
... A34: 5. Ne pas commander 500 unités avant validation du MVP sur échantillons (cahier des charges, Partie 10) ; le capital à immobiliser par palier est calculé dans Coût lunettes.

Sheet Hypothèses
A1: VELA / IRIS — Hypothèses (toutes les entrées modifiables sont en bleu ; fond jaune = levier clé)
A3: 1. Général
A4: Paramètre | B4: Valeur | F4: Source / note
A5: Taux de change USD → CAD | B5: 1.36 | F5: Hypothèse (Banque du Canada, ~1,36 en 2026). Tous les prix affichés en CAD sauf mention US$.
A6: Taxes de vente Québec (TPS 5 % + TVQ 9,975 %) | B6: 0.14975 | F6: Revenu Québec. Les prix du modèle sont hors taxes ; le prix TTC est calculé à titre indicatif.
A7: Frais de paiement Stripe — % du montant | B7: 0.029 | F7: Stripe Canada : 2,9 % + 0,30 $ par transaction (cartes canadiennes).
A8: Frais de paiement Stripe — fixe par transaction (CAD) | B8: 0.3
A9: Palier de volume retenu pour le prix de vente (100 / 500 / 1000 / 5000) | B9: 500 | F9: Le prix public est fixé sur ce palier ; la marge réelle s'améliore avec le volume.
A10: Marge brute cible sur les lunettes (hors abonnement) | B10: 0.45 | F10: Standard électronique grand public : 35–50 %. Meta vend les Ray-Ban Meta ~379 US$ pour un coût matière estimé ~150 US$.
A12: 2. Matériel — lunettes K900 (SmartXY) — coûts unitaires
A13: Poste | B13: 100 unités | C13: 500 unités | D13: 1 000 unités | E13: 5 000 unités | F13: Source / note
A14: Prix OEM K900 par unité (US$) | B14: 145 | C14: 125 | D14: 110 | E14: 95 | F14: HYPOTHÈSE À REMPLACER par le devis SmartXY (RFQ, Partie 10 du cahier des charges). Fourchette Alibaba 2026 pour des lunettes caméra 13 MP + audio : 45–205 US$ selon chipset ; le K900 (Android, MTK + BES, Sony 13 MP, 5 micros) se situe dans le haut de la fourchette.
A15: Quantité du palier | B15: 100 | C15: 500 | D15: 1000 | E15: 5000
A16: Frais non récurrents OEM : firmware, logo, packaging (US$, total) | B16: 15000 | F16: Hypothèse : personnalisation firmware (voyant, déclic sonore), gravure VELA, boîte. Amorti sur les unités du palier.
A17: Fret + assurance par unité (US$) | B17: 6 | F17: Hypothèse : fret aérien groupé Shenzhen → Montréal, ~300 g emballé.
A18: Droits de douane et courtage (% du prix OEM) | B18: 0.05 | F18: Hypothèse prudente. Vérifier le code SH (9004 lunettes vs 8525 caméras) auprès de l'ASFC ; certains codes sont à 0 %.
A19: Emballage de vente + étui + câble (US$) | B19: 8
A20: Réserve garantie 1 an (% du prix OEM) | B20: 0.04 | F20: Hypothèse : 4 % de taux de défaut couvert par remplacement.
A21: Préparation + expédition au client (CAD) | B21: 12 | F21: Postes Canada / Purolator colis léger au Québec, étiquette + main-d'œuvre.
A22: Retours et remboursements (% des ventes) | B22: 0.03
A24: 3. Repères de prix concurrents (prix public, US$ hors taxes)
A25: Produit | B25: Prix US$ | F25: Source
A26: Meta Glasses (sans marque Ray-Ban, juin 2026) | B26: 299 | F26: CNBC, 23 juin 2026 — cnbc.com/2026/06/23/meta-glasses-are-new-smart-glasses-starting-at-299.html
A27: Ray-Ban Meta (Gen 2/3) | B27: 379 | F27: TechCrunch, 31 mars 2026 — 'begin at $379'
A28: Ray-Ban Meta prescription (optique) | B28: 499 | F28: TechCrunch, 31 mars 2026
A29: Meta Ray-Ban Display (avec écran) | B29: 799 | F29: Meta.com / TechCrunch
A30: Snap Specs (AR, autonome) | B30: 2195 | F30: Tom's Guide 2026 — précommande
A32: 4. Prix des API (US$ par million de jetons) — modèles réellement câblés dans IRIS
A33: Modèle | B33: Entrée | C33: Sortie | D33: Vision (image) | F33: Source (vérifié le 2 sept. 2026)
A34: OpenRouter — minimax/minimax-m3:free (défaut IRIS) | B34: 0 | C34: 0 | D34: =B34 -> 0 | F34: OpenRouter, palier gratuit (limites de débit, bascule automatique). Aucun coût mais aucune garantie de disponibilité.
A35: Google Gemini 2.5 Flash | B35: 0.3 | C35: 2.5 | D35: =B35 -> 0.3 | F35: ai.google.dev/gemini-api/docs/pricing — modèle par défaut du connecteur Gemini d'IRIS.
A36: Google Gemini 3.7 Flash | B36: 0.75 | C36: 3.75 | D36: =B36 -> 0.75 | F36: ai.google.dev — DOUBLE au 1er janvier 2027 (1,50 / 7,50).
A37: Google Gemini 2.5 Pro | B37: 1.25 | C37: 10 | D37: =B37 -> 1.25 | F37: ai.google.dev — prompts ≤ 200k jetons.
A38: OpenAI GPT-5 mini | B38: 0.25 | C38: 2 | D38: =B38 -> 0.25 | F38: openai.com/api/pricing (via pricepertoken.com) — défaut du connecteur GPT d'IRIS.
A39: OpenAI GPT-5 | B39: 1.25 | C39: 10 | D39: =B39 -> 1.25 | F39: openai.com/api/pricing (via cloudzero.com).
A40: Anthropic Claude Haiku 4.5 | B40: 1 | C40: 5 | D40: =B40 -> 1 | F40: Référence tarifaire Anthropic (skill claude-api, cache 24 juin 2026).
A41: Anthropic Claude Sonnet 5 | B41: 2 | C41: 10 | D41: =B41 -> 2 | F41: Référence tarifaire Anthropic.
A42: Anthropic Claude Opus 5 (défaut IRIS) | B42: 5 | C42: 25 | D42: =B42 -> 5 | F42: Référence tarifaire Anthropic — modèle Claude par défaut dans config.py.
A43: Anthropic Claude Fable 5.1 | B43: 10 | C43: 50 | D43: =B43 -> 10 | F43: Référence tarifaire Anthropic — réservé aux tâches complexes.
A44: Jetons par capture d'écran envoyée au modèle de vision | B44: 1600 | F44: Ordre de grandeur pour une image 1 280×800 (≈ largeur×hauteur/750 chez Anthropic).
...

Sheet Coût lunettes
A1: Coût de revient et prix de vente des lunettes VELA (K900 + IRIS)
A2: Toutes les valeurs sont calculées à partir de la feuille Hypothèses. Colonnes = palier de commande OEM.
A4: Poste (par unité) | B4: 100 unités | C4: 500 unités | D4: 1 000 unités | E4: 5 000 unités | F4: Formule / note
A5: Quantité commandée | B5: =Hypothèses!B15 -> 100 | C5: =Hypothèses!C15 -> 500 | D5: =Hypothèses!D15 -> 1000 | E5: =Hypothèses!E15 -> 5000
A6: Prix OEM (US$) | B6: =Hypothèses!B14 -> 145 | C6: =Hypothèses!C14 -> 125 | D6: =Hypothèses!D14 -> 110 | E6: =Hypothèses!E14 -> 95 | F6: Devis SmartXY à insérer dans Hypothèses.
A7: Frais non récurrents amortis (US$) | B7: =Hypothèses!$B$16/B5 -> 150 | C7: =Hypothèses!$B$16/C5 -> 30 | D7: =Hypothèses!$B$16/D5 -> 15 | E7: =Hypothèses!$B$16/E5 -> 3
A8: Fret + assurance (US$) | B8: =Hypothèses!$B$17 -> 6 | C8: =Hypothèses!$B$17 -> 6 | D8: =Hypothèses!$B$17 -> 6 | E8: =Hypothèses!$B$17 -> 6
A9: Douane + courtage (US$) | B9: =B6*Hypothèses!$B$18 -> 7.25 | C9: =C6*Hypothèses!$B$18 -> 6.25 | D9: =D6*Hypothèses!$B$18 -> 5.5 | E9: =E6*Hypothèses!$B$18 -> 4.75
A10: Emballage, étui, câble (US$) | B10: =Hypothèses!$B$19 -> 8 | C10: =Hypothèses!$B$19 -> 8 | D10: =Hypothèses!$B$19 -> 8 | E10: =Hypothèses!$B$19 -> 8
A11: Réserve garantie (US$) | B11: =B6*Hypothèses!$B$20 -> 5.8 | C11: =C6*Hypothèses!$B$20 -> 5 | D11: =D6*Hypothèses!$B$20 -> 4.4 | E11: =E6*Hypothèses!$B$20 -> 3.8
A12: Coût rendu entrepôt (US$) | B12: =SUM(B6:B11) -> 322.05 | C12: =SUM(C6:C11) -> 180.25 | D12: =SUM(D6:D11) -> 148.9 | E12: =SUM(E6:E11) -> 120.55
A13: Coût rendu entrepôt (CAD) | B13: =B12*Hypothèses!$B$5 -> 437.988 | C13: =C12*Hypothèses!$B$5 -> 245.14 | D13: =D12*Hypothèses!$B$5 -> 202.504 | E13: =E12*Hypothèses!$B$5 -> 163.948 | F13: Conversion au taux de la feuille Hypothèses.
A14: Préparation + expédition client (CAD) | B14: =Hypothèses!$B$21 -> 12 | C14: =Hypothèses!$B$21 -> 12 | D14: =Hypothèses!$B$21 -> 12 | E14: =Hypothèses!$B$21 -> 12
A15: COÛT DE REVIENT COMPLET (CAD, hors retours et paiement) | B15: =B13+B14 -> 449.988 | C15: =C13+C14 -> 257.14 | D15: =D13+D14 -> 214.504 | E15: =E13+E14 -> 175.948
A17: Prix de vente
A18: Prix HT nécessaire pour la marge cible (CAD) | B18: =B15/(1-Hypothèses!$B$10-Hypothèses!$B$22-Hypothèses!$B$7) -> 916.47251 | C18: =C15/(1-Hypothèses!$B$10-Hypothèses!$B$22-Hypothèses!$B$7) -> 523.70672 | D18: =D15/(1-Hypothèses!$B$10-Hypothèses!$B$22-Hypothèses!$B$7) -> 436.87169 | E18: =E15/(1-Hypothèses!$B$10-Hypothèses!$B$22-Hypothèses!$B$7) -> 358.34623 | F18: Formule : coût / (1 − marge cible − retours − frais Stripe %). La marge cible est nette des retours et des frais de paiement.
A19: Prix public recommandé HT (CAD, arrondi psychologique x49/x99) | B19: =CEILING(B18,50)-1 -> 949 | C19: =CEILING(C18,50)-1 -> 549 | D19: =CEILING(D18,50)-1 -> 449 | E19: =CEILING(E18,50)-1 -> 399
A20: Prix TTC affiché au Québec (CAD) | B20: =B19*(1+Hypothèses!$B$6) -> 1091.1128 | C20: =C19*(1+Hypothèses!$B$6) -> 631.21275 | D20: =D19*(1+Hypothèses!$B$6) -> 516.23775 | E20: =E19*(1+Hypothèses!$B$6) -> 458.75025
A21: Équivalent US$ (pour comparer aux concurrents) | B21: =B19/Hypothèses!$B$5 -> 697.79412 | C21: =C19/Hypothèses!$B$5 -> 403.67647 | D21: =D19/Hypothèses!$B$5 -> 330.14706 | E21: =E19/Hypothèses!$B$5 -> 293.38235
A22: Frais Stripe par vente (CAD) | B22: =B19*Hypothèses!$B$7+Hypothèses!$B$8 -> 27.821 | C22: =C19*Hypothèses!$B$7+Hypothèses!$B$8 -> 16.221 | D22: =D19*Hypothèses!$B$7+Hypothèses!$B$8 -> 13.321 | E22: =E19*Hypothèses!$B$7+Hypothèses!$B$8 -> 11.871
A23: Coût des retours par vente (CAD) | B23: =B19*Hypothèses!$B$22 -> 28.47 | C23: =C19*Hypothèses!$B$22 -> 16.47 | D23: =D19*Hypothèses!$B$22 -> 13.47 | E23: =E19*Hypothèses!$B$22 -> 11.97
A24: Marge brute par paire vendue (CAD) | B24: =B19-B15-B22-B23 -> 442.721 | C24: =C19-C15-C22-C23 -> 259.169 | D24: =D19-D15-D22-D23 -> 207.705 | E24: =E19-E15-E22-E23 -> 199.211
A25: Marge brute réelle (%) | B25: =IF(B19=0,0,B24/B19) -> 0.46651317 | C25: =IF(C19=0,0,C24/C19) -> 0.47207468 | D25: =IF(D19=0,0,D24/D19) -> 0.46259465 | E25: =IF(E19=0,0,E24/E19) -> 0.49927569
A26: Capital à immobiliser pour la commande (CAD, rendu entrepôt) | B26: =B13*B5 -> 43798.8 | C26: =C13*C5 -> 122570 | D26: =D13*D5 -> 202504 | E26: =E13*E5 -> 819740 | F26: Trésorerie nécessaire avant la première vente du palier (hors marketing).
A28: Prix retenu (palier choisi dans Hypothèses)
A29: Palier choisi | B29: =Hypothèses!$B$9 -> 500
A30: Prix public HT retenu (CAD) | B30: =INDEX(B19:E19,MATCH(Hypothèses!$B$9,B5:E5,0)) -> 549
A31: Coût de revient complet retenu (CAD) | B31: =INDEX(B15:E15,MATCH(Hypothèses!$B$9,B5:E5,0)) -> 257.14
A32: Marge brute par paire retenue (CAD) | B32: =INDEX(B24:E24,MATCH(Hypothèses!$B$9,B5:E5,0)) -> 259.169
A33: Prix TTC retenu (CAD) | B33: ='Coût lunettes'!$B$30*(1+Hypothèses!$B$6) -> 631.21275
A35: Positionnement face aux concurrents (convertis en CAD)
A36: Produit | B36: Prix US$ | C36: Prix CAD | D36: Écart VELA vs concurrent
A37: =Hypothèses!A26 -> Meta Glasses (sans marque Ray-Ban, juin 2026) | B37: =Hypothèses!B26 -> 299 | C37: =B37*Hypothèses!$B$5 -> 406.64 | D37: =IF(C37=0,0,'Coût lunettes'!$B$30/C37-1) -> 0.35008853
A38: =Hypothèses!A27 -> Ray-Ban Meta (Gen 2/3) | B38: =Hypothèses!B27 -> 379 | C38: =B38*Hypothèses!$B$5 -> 515.44 | D38: =IF(C38=0,0,'Coût lunettes'!$B$30/C38-1) -> 0.065109421
A39: =Hypothèses!A28 -> Ray-Ban Meta prescription (optique) | B39: =Hypothèses!B28 -> 499 | C39: =B39*Hypothèses!$B$5 -> 678.64 | D39: =IF(C39=0,0,'Coût lunettes'!$B$30/C39-1) -> -0.19102912
A40: =Hypothèses!A29 -> Meta Ray-Ban Display (avec écran) | B40: =Hypothèses!B29 -> 799 | C40: =B40*Hypothèses!$B$5 -> 1086.64 | D40: =IF(C40=0,0,'Coût lunettes'!$B$30/C40-1) -> -0.49477288
A41: =Hypothèses!A30 -> Snap Specs (AR, autonome) | B41: =Hypothèses!B30 -> 2195 | C41: =B41*Hypothèses!$B$5 -> 2985.2 | D41: =IF(C41=0,0,'Coût lunettes'!$B$30/C41-1) -> -0.81609272
A42: VELA (prix HT retenu) | B42: ='Coût lunettes'!$B$30/Hypothèses!$B$5 -> 403.67647 | C42: ='Coût lunettes'!$B$30 -> 549
A44: Lecture : VELA n'a pas d'écran ni de marque de lunetier ; le différenciateur est IRIS (confidentialité, contrôle du PC, agents au choix). Rester sous les Ray-Ban Meta (379 US$) et au-dessus des Meta Glasses (299 US$) est cohérent tant que le coût OEM reste ≤ 125 US$.

Sheet Coût API par utilisateur
A1: Coût variable des API par utilisateur et par mois (CAD)
A2: Trois profils d'usage (Hypothèses §6). Chaque ligne « modèle » donne le coût mensuel si TOUTES les requêtes passaient par ce modèle.
A4: Poste | B4: Léger | C4: Moyen | D4: Intensif | E4: Note
A5: Requêtes par mois | B5: =Hypothèses!B65*Hypothèses!B66 -> 160 | C5: =Hypothèses!C65*Hypothèses!C66 -> 520 | D5: =Hypothèses!D65*Hypothèses!D66 -> 1200
A6: Jetons d'entrée par mois (texte) | B6: =B5*Hypothèses!B67 -> 400000 | C6: =C5*Hypothèses!C67 -> 1560000 | D6: =D5*Hypothèses!D67 -> 4200000
A7: Jetons d'entrée par mois (captures d'écran) | B7: =B5*Hypothèses!B71*Hypothèses!$B$44 -> 12800 | C7: =C5*Hypothèses!C71*Hypothèses!$B$44 -> 83200 | D7: =D5*Hypothèses!D71*Hypothèses!$B$44 -> 384000
A8: Jetons de sortie par mois | B8: =B5*Hypothèses!B68 -> 12800 | C8: =C5*Hypothèses!C68 -> 62400 | D8: =D5*Hypothèses!D68 -> 192000
A10: A. Modèle de langage — coût mensuel selon le modèle (CAD)
A11: OpenRouter — minimax/minimax-m3:free (défaut IRIS) | B11: =((B6+B7)*Hypothèses!$B$34+B8*Hypothèses!$C$34)/1000000*Hypothèses!$B$5 -> 0 | C11: =((C6+C7)*Hypothèses!$B$34+C8*Hypothèses!$C$34)/1000000*Hypothèses!$B$5 -> 0 | D11: =((D6+D7)*Hypothèses!$B$34+D8*Hypothèses!$C$34)/1000000*Hypothèses!$B$5 -> 0
A12: Google Gemini 2.5 Flash | B12: =((B6+B7)*Hypothèses!$B$35+B8*Hypothèses!$C$35)/1000000*Hypothèses!$B$5 -> 0.2119424 | C12: =((C6+C7)*Hypothèses!$B$35+C8*Hypothèses!$C$35)/1000000*Hypothèses!$B$5 -> 0.8825856 | D12: =((D6+D7)*Hypothèses!$B$35+D8*Hypothèses!$C$35)/1000000*Hypothèses!$B$5 -> 2.523072
A13: Google Gemini 3.7 Flash | B13: =((B6+B7)*Hypothèses!$B$36+B8*Hypothèses!$C$36)/1000000*Hypothèses!$B$5 -> 0.486336 | C13: =((C6+C7)*Hypothèses!$B$36+C8*Hypothèses!$C$36)/1000000*Hypothèses!$B$5 -> 1.994304 | D13: =((D6+D7)*Hypothèses!$B$36+D8*Hypothèses!$C$36)/1000000*Hypothèses!$B$5 -> 5.65488
A14: Google Gemini 2.5 Pro | B14: =((B6+B7)*Hypothèses!$B$37+B8*Hypothèses!$C$37)/1000000*Hypothèses!$B$5 -> 0.87584 | C14: =((C6+C7)*Hypothèses!$B$37+C8*Hypothèses!$C$37)/1000000*Hypothèses!$B$5 -> 3.64208 | D14: =((D6+D7)*Hypothèses!$B$37+D8*Hypothèses!$C$37)/1000000*Hypothèses!$B$5 -> 10.404
A15: OpenAI GPT-5 mini | B15: =((B6+B7)*Hypothèses!$B$38+B8*Hypothèses!$C$38)/1000000*Hypothèses!$B$5 -> 0.175168 | C15: =((C6+C7)*Hypothèses!$B$38+C8*Hypothèses!$C$38)/1000000*Hypothèses!$B$5 -> 0.728416 | D15: =((D6+D7)*Hypothèses!$B$38+D8*Hypothèses!$C$38)/1000000*Hypothèses!$B$5 -> 2.0808
A16: OpenAI GPT-5 | B16: =((B6+B7)*Hypothèses!$B$39+B8*Hypothèses!$C$39)/1000000*Hypothèses!$B$5 -> 0.87584 | C16: =((C6+C7)*Hypothèses!$B$39+C8*Hypothèses!$C$39)/1000000*Hypothèses!$B$5 -> 3.64208 | D16: =((D6+D7)*Hypothèses!$B$39+D8*Hypothèses!$C$39)/1000000*Hypothèses!$B$5 -> 10.404
A17: Anthropic Claude Haiku 4.5 | B17: =((B6+B7)*Hypothèses!$B$40+B8*Hypothèses!$C$40)/1000000*Hypothèses!$B$5 -> 0.648448 | C17: =((C6+C7)*Hypothèses!$B$40+C8*Hypothèses!$C$40)/1000000*Hypothèses!$B$5 -> 2.659072 | D17: =((D6+D7)*Hypothèses!$B$40+D8*Hypothèses!$C$40)/1000000*Hypothèses!$B$5 -> 7.53984
A18: Anthropic Claude Sonnet 5 | B18: =((B6+B7)*Hypothèses!$B$41+B8*Hypothèses!$C$41)/1000000*Hypothèses!$B$5 -> 1.296896 | C18: =((C6+C7)*Hypothèses!$B$41+C8*Hypothèses!$C$41)/1000000*Hypothèses!$B$5 -> 5.318144 | D18: =((D6+D7)*Hypothèses!$B$41+D8*Hypothèses!$C$41)/1000000*Hypothèses!$B$5 -> 15.07968
A19: Anthropic Claude Opus 5 (défaut IRIS) | B19: =((B6+B7)*Hypothèses!$B$42+B8*Hypothèses!$C$42)/1000000*Hypothèses!$B$5 -> 3.24224 | C19: =((C6+C7)*Hypothèses!$B$42+C8*Hypothèses!$C$42)/1000000*Hypothèses!$B$5 -> 13.29536 | D19: =((D6+D7)*Hypothèses!$B$42+D8*Hypothèses!$C$42)/1000000*Hypothèses!$B$5 -> 37.6992
A20: Anthropic Claude Fable 5.1 | B20: =((B6+B7)*Hypothèses!$B$43+B8*Hypothèses!$C$43)/1000000*Hypothèses!$B$5 -> 6.48448 | C20: =((C6+C7)*Hypothèses!$B$43+C8*Hypothèses!$C$43)/1000000*Hypothèses!$B$5 -> 26.59072 | D20: =((D6+D7)*Hypothèses!$B$43+D8*Hypothèses!$C$43)/1000000*Hypothèses!$B$5 -> 75.3984
A22: B. Voix ElevenLabs (CAD)
A23: Caractères synthétisés par mois | B23: =B5*Hypothèses!B69 -> 24000 | C23: =C5*Hypothèses!C69 -> 104000 | D23: =D5*Hypothèses!D69 -> 312000
A24: Crédits ElevenLabs consommés | B24: =B23*Hypothèses!$B$58 -> 12000 | C24: =C23*Hypothèses!$B$58 -> 52000 | D24: =D23*Hypothèses!$B$58 -> 156000
A25: Coût ElevenLabs au tarif marginal du plan (CAD) | B25: =B24/1000*Hypothèses!$B$57*Hypothèses!$B$5 -> 2.7109333 | C25: =C24/1000*Hypothèses!$B$57*Hypothèses!$B$5 -> 11.747378 | D25: =D24/1000*Hypothèses!$B$57*Hypothèses!$B$5 -> 35.242133 | E25: Le plan a un coût fixe (Hypothèses §7) ; ici seulement le coût par caractère.
A26: Comparaison : même volume avec la voix OpenAI (CAD) | B26: =B23/1000*Hypothèses!$B$59*Hypothèses!$B$5 -> 0.4896 | C26: =C23/1000*Hypothèses!$B$59*Hypothèses!$B$5 -> 2.1216 | D26: =D23/1000*Hypothèses!$B$59*Hypothèses!$B$5 -> 6.3648 | E26: Levier n°1 si la marge des plans d'entrée est trop faible.
A27: Utilisateurs couverts par les crédits du plan (indicatif) | B27: =IF(B24=0,0,Hypothèses!$B$56/B24) -> 150 | C27: =IF(C24=0,0,Hypothèses!$B$56/C24) -> 34.615385 | D27: =IF(D24=0,0,Hypothèses!$B$56/D24) -> 11.538462 | E27: Au-delà, dépassement facturé ou plan supérieur.
A29: C. Reconnaissance vocale (CAD)
A30: Minutes audio envoyées au cloud par mois | B30: =B5*Hypothèses!B70*Hypothèses!$B$61 -> 4.8 | C30: =C5*Hypothèses!C70*Hypothèses!$B$61 -> 18.72 | D30: =D5*Hypothèses!D70*Hypothèses!$B$61 -> 54 | E30: Le reste est traité hors-ligne par Vosk (gratuit).
A31: Coût reconnaissance cloud (CAD) | B31: =B30*Hypothèses!$B$60*Hypothèses!$B$5 -> 0.104448 | C31: =C30*Hypothèses!$B$60*Hypothèses!$B$5 -> 0.4073472 | D31: =D30*Hypothèses!$B$60*Hypothèses!$B$5 -> 1.17504
A33: D. Coût variable total par utilisateur selon la pile de modèles (CAD/mois)
A34: Pile GRATUIT : OpenRouter gratuit + voix Windows (pas d'ElevenLabs) | B34: =B11*1 -> 0 | C34: =C11*1 -> 0 | D34: =D11*1 -> 0
A35: Pile ESSENTIEL : Gemini 2.5 Flash 70 % + GPT-5 mini 30 % + ElevenLabs | B35: =B12*0.7+B15*0.3+B25+B31 -> 3.0162914 | C35: =C12*0.7+C15*0.3+C25+C31 -> 12.99106 | D35: =D12*0.7+D15*0.3+D25+D31 -> 38.807564
A36: Pile PRO : Claude Sonnet 5 60 % + Gemini 2.5 Flash 30 % + GPT-5 10 % + ElevenLabs | B36: =B18*0.6+B12*0.3+B16*0.1+B25+B31 -> 3.7446857 | C36: =C18*0.6+C12*0.3+C16*0.1+C25+C31 -> 15.974595 | D36: =D18*0.6+D12*0.3+D16*0.1+D25+D31 -> 47.262303
A37: Pile ULTRA : Claude Opus 5 50 % + Claude Sonnet 5 30 % + GPT-5 20 % + ElevenLabs | B37: =B19*0.5+B18*0.3+B16*0.2+B25+B31 -> 5.0007381 | C37: =C19*0.5+C18*0.3+C16*0.2+C25+C31 -> 21.126264 | D37: =D19*0.5+D18*0.3+D16*0.2+D25+D31 -> 61.871477
A39: Lecture : la voix ElevenLabs est le premier poste de coût en usage intensif ; le modèle de langage ne pèse vraiment qu'avec Claude Opus 5. D'où l'intérêt de réserver Opus aux tâches longues (reasoning_model) et de garder un modèle rapide pour la voix (voice_model).

Sheet Abonnements
A1: Plans d'abonnement IRIS — prix, coût par abonné et marge (CAD, hors taxes)
A2: Les prix mensuels sont des entrées (bleu). Le coût par abonné vient de la feuille Coût API selon le profil d'usage associé au plan.
B4: GRATUIT | C4: ESSENTIEL | D4: PRO | E4: ULTRA | F4: Note
A5: Prix mensuel HT (CAD) | B5: 0 | C5: 19.99 | D5: 29.99 | E5: 99.99 | F5: Repère marché : ChatGPT Plus / Claude Pro / Google AI Pro = 20 US$ ≈ 27 CAD. PRO doit rester proche de ce repère ; ULTRA inclut Opus 5.
A6: Prix annuel HT (CAD) — 2 mois offerts | B6: =B5*10 -> 0 | C6: =C5*10 -> 199.9 | D6: =D5*10 -> 299.9 | E6: =E5*10 -> 999.9
A7: Profil d'usage associé (Léger / Moyen / Intensif) | B7: Léger | C7: Moyen | D7: Moyen | E7: Intensif
A8: Pile de modèles (voir Coût API §D) | B8: Gratuit | C8: Essentiel | D8: Pro | E8: Ultra
A9: Quota de requêtes vocales par mois | B9: 150 | C9: 500 | D9: 800 | E9: 1500 | F9: Plafond « fair use » à coder dans IRIS pour borner le coût d'un abonné intensif.
A10: Ce qui est inclus | B10: Modèles gratuits OpenRouter (minimax-m3:free), voix Windows, contrôle du PC, Vosk hors-ligne. Clés API personnelles possibles. | C10: Voix ElevenLabs « Mélanie », Gemini 2.5 Flash + GPT-5 mini, sites web enregistrés (Omnivox…), routines, rappels. | D10: Tout ESSENTIEL + Claude Sonnet 5 pour le raisonnement, vision de l'écran (computer_use), résumé quotidien, mémoire. | E10: Tout PRO + Claude Opus 5 pour les tâches longues, quota élevé, support prioritaire, accès anticipé aux nouveautés.
A12: Coût et marge par abonné (CAD/mois)
A13: Coût API variable par abonné | B13: =INDEX('Coût API par utilisateur'!$B$34:$D$34,1,MATCH(B7,'Coût API par utilisateur'!$B$4:$D$4,0)) -> 0 | C13: =INDEX('Coût API par utilisateur'!$B$35:$D$35,1,MATCH(C7,'Coût API par utilisateur'!$B$4:$D$4,0)) -> 12.99106 | D13: =INDEX('Coût API par utilisateur'!$B$36:$D$36,1,MATCH(D7,'Coût API par utilisateur'!$B$4:$D$4,0)) -> 15.974595 | E13: =INDEX('Coût API par utilisateur'!$B$37:$D$37,1,MATCH(E7,'Coût API par utilisateur'!$B$4:$D$4,0)) -> 61.871477
A14: Frais Stripe | B14: =IF(B5=0,0,B5*Hypothèses!$B$7+Hypothèses!$B$8) -> 0 | C14: =IF(C5=0,0,C5*Hypothèses!$B$7+Hypothèses!$B$8) -> 0.87971 | D14: =IF(D5=0,0,D5*Hypothèses!$B$7+Hypothèses!$B$8) -> 1.16971 | E14: =IF(E5=0,0,E5*Hypothèses!$B$7+Hypothèses!$B$8) -> 3.19971
A15: Marge brute par abonné (CAD) | B15: =B5-B13-B14 -> 0 | C15: =C5-C13-C14 -> 6.1192303 | D15: =D5-D13-D14 -> 12.845695 | E15: =E5-E13-E14 -> 34.918813
A16: Marge brute (%) | B16: =IF(B5=0,0,B15/B5) -> 0 | C16: =IF(C5=0,0,C15/C5) -> 0.30611457 | D16: =IF(D5=0,0,D15/D5) -> 0.42833261 | E16: =IF(E5=0,0,E15/E5) -> 0.34922305
A17: Coût API si l'abonné consomme tout son quota (pire cas) | B17: =IF(B9=0,0,B13*B9/INDEX('Coût API par utilisateur'!$B$5:$D$5,1,MATCH(B7,'Coût API par utilisateur'!$B$4:$D$4,0))) -> 0 | C17: =IF(C9=0,0,C13*C9/INDEX('Coût API par utilisateur'!$B$5:$D$5,1,MATCH(C7,'Coût API par utilisateur'!$B$4:$D$4,0))) -> 12.491404 | D17: =IF(D9=0,0,D13*D9/INDEX('Coût API par utilisateur'!$B$5:$D$5,1,MATCH(D7,'Coût API par utilisateur'!$B$4:$D$4,0))) -> 24.5763 | E17: =IF(E9=0,0,E13*E9/INDEX('Coût API par utilisateur'!$B$5:$D$5,1,MATCH(E7,'Coût API par utilisateur'!$B$4:$D$4,0))) -> 77.339347
A18: Marge brute au pire cas (%) | B18: =IF(B5=0,0,(B5-B17-B14)/B5) -> 0 | C18: =IF(C5=0,0,(C5-C17-C14)/C5) -> 0.33110988 | D18: =IF(D5=0,0,(D5-D17-D14)/D5) -> 0.1415135 | E18: =IF(E5=0,0,(E5-E17-E14)/E5) -> 0.19452889 | F18: Doit rester positif : sinon baisser le quota ou monter le prix.
A20: Offres groupées lunettes + abonnement
A21: Offre | B21: Prix HT (CAD) | C21: Coût (CAD) | D21: Marge brute (CAD) | F21: Note
A22: Lunettes seules | B22: ='Coût lunettes'!$B$30 -> 549 | C22: ='Coût lunettes'!$B$31 -> 257.14 | D22: =B22-C22-B22*(Hypothèses!$B$7+Hypothèses!$B$22)-Hypothèses!$B$8 -> 259.169
A23: Lunettes + 12 mois PRO (remise sur l'abonnement) | B23: =CEILING('Coût lunettes'!$B$30+D5*12*(1-F23),10)-1 -> 839 | C23: ='Coût lunettes'!$B$31+D13*12 -> 448.83514 | D23: =B23-C23-B23*(Hypothèses!$B$7+Hypothèses!$B$22)-Hypothèses!$B$8 -> 340.36386 | F23: 0.2
A24: Lunettes + 12 mois ULTRA (remise sur l'abonnement) | B24: =CEILING('Coût lunettes'!$B$30+E5*12*(1-F24),10)-1 -> 1509 | C24: ='Coût lunettes'!$B$31+E13*12 -> 999.59773 | D24: =B24-C24-B24*(Hypothèses!$B$7+Hypothèses!$B$22)-Hypothèses!$B$8 -> 420.07127 | F24: 0.2
A26: Règle importante : les abonnements grand public ChatGPT Plus, Claude Pro et Google AI Pro couvrent ton usage personnel et le développement. Pour servir des clients, IRIS doit appeler les API (facturées à l'usage, prépayées) — ce sont ces coûts qui figurent ici. Revendre l'accès via un compte grand public viole les conditions d'utilisation.

Sheet Projection 12 mois
A1: Projection 12 mois — ventes de lunettes + abonnements (CAD, hors taxes)
A3: Leviers (entrées)
A4: Part des acheteurs qui prennent un abonnement payant | B4: 0.6
A5: Répartition des abonnés payants : ESSENTIEL / PRO / ULTRA | B5: 0.5 | C5: 0.4 | D5: 0.1 | E5: =B5+C5+D5 -> 1 | F5: ← doit faire 100 %
A6: Désabonnement mensuel (churn) | B6: 0.05
A7: Abonnés logiciel seuls (sans lunettes) recrutés par mois, en % des lunettes vendues | B7: 0.5 | F7: IRIS fonctionne aussi sans lunettes (app Windows) : source d'abonnés supplémentaire.
A9: Poste | B9: Mois 1 | C9: Mois 2 | D9: Mois 3 | E9: Mois 4 | F9: Mois 5 | G9: Mois 6 | H9: Mois 7 | I9: Mois 8 | J9: Mois 9 | K9: Mois 10 | L9: Mois 11 | M9: Mois 12 | N9: Total / fin
A10: Lunettes vendues (entrée) | B10: 5 | C10: 10 | D10: 15 | E10: 20 | F10: 30 | G10: 40 | H10: 50 | I10: 60 | J10: 80 | K10: 100 | L10: 120 | M10: 150 | N10: =SUM(B10:M10) -> 680
A11: Revenu lunettes | B11: =B10*'Coût lunettes'!$B$30 -> 2745 | C11: =C10*'Coût lunettes'!$B$30 -> 5490 | D11: =D10*'Coût lunettes'!$B$30 -> 8235 | E11: =E10*'Coût lunettes'!$B$30 -> 10980 | F11: =F10*'Coût lunettes'!$B$30 -> 16470 | G11: =G10*'Coût lunettes'!$B$30 -> 21960 | H11: =H10*'Coût lunettes'!$B$30 -> 27450 | I11: =I10*'Coût lunettes'!$B$30 -> 32940 | ... M11: =M10*'Coût lunettes'!$B$30 -> 82350 | N11: =SUM(B11:M11) -> 373320
A12: Coût des lunettes vendues (coût de revient + Stripe + retours) | B12: =B10*('Coût lunettes'!$B$31+'Coût lunettes'!$B$30*(Hypothèses!$B$7+Hypothèses!$B$22)+Hypothèses!$B$8) -> 1449.155 | C12: =C10*('Coût lunettes'!$B$31+'Coût lunettes'!$B$30*(Hypothèses!$B$7+Hypothèses!$B$22)+Hypothèses!$B$8) -> 2898.31 | D12: =D10*('Coût lunettes'!$B$31+'Coût lunettes'!$B$30*(Hypothèses!$B$7+Hypothèses!$B$22)+Hypothèses!$B$8) -> 4347.465 | E12: =E10*('Coût lunettes'!$B$31+'Coût lunettes'!$B$30*(Hypothèses!$B$7+Hypothèses!$B$22)+Hypothèses!$B$8) -> 5796.62 | F12: =F10*('Coût lunettes'!$B$31+'Coût lunettes'!$B$30*(Hypothèses!$B$7+Hypothèses!$B$22)+Hypothèses!$B$8) -> 8694.93 | G12: =G10*('Coût lunettes'!$B$31+'Coût lunettes'!$B$30*(Hypothèses!$B$7+Hypothèses!$B$22)+Hypothèses!$B$8) -> 11593.24 | H12: =H10*('Coût lunettes'!$B$31+'Coût lunettes'!$B$30*(Hypothèses!$B$7+Hypothèses!$B$22)+Hypothèses!$B$8) -> 14491.55 | I12: =I10*('Coût lunettes'!$B$31+'Coût lunettes'!$B$30*(Hypothèses!$B$7+Hypothèses!$B$22)+Hypothèses!$B$8) -> 17389.86 | ... M12: =M10*('Coût lunettes'!$B$31+'Coût lunettes'!$B$30*(Hypothèses!$B$7+Hypothèses!$B$22)+Hypothèses!$B$8) -> 43474.65 | N12: =SUM(B12:M12) -> 197085.08
A13: Marge brute lunettes | B13: =B11-B12 -> 1295.845 | C13: =C11-C12 -> 2591.69 | D13: =D11-D12 -> 3887.535 | E13: =E11-E12 -> 5183.38 | F13: =F11-F12 -> 7775.07 | G13: =G11-G12 -> 10366.76 | H13: =H11-H12 -> 12958.45 | I13: =I11-I12 -> 15550.14 | ... M13: =M11-M12 -> 38875.35 | N13: =SUM(B13:M13) -> 176234.92
A15: Nouveaux abonnés ESSENTIEL | B15: =ROUND(B10*(1+'Projection 12 mois'!$B$7)*'Projection 12 mois'!$B$4*'Projection 12 mois'!$B$5,0) -> 2 | C15: =ROUND(C10*(1+'Projection 12 mois'!$B$7)*'Projection 12 mois'!$B$4*'Projection 12 mois'!$B$5,0) -> 5 | D15: =ROUND(D10*(1+'Projection 12 mois'!$B$7)*'Projection 12 mois'!$B$4*'Projection 12 mois'!$B$5,0) -> 7 | E15: =ROUND(E10*(1+'Projection 12 mois'!$B$7)*'Projection 12 mois'!$B$4*'Projection 12 mois'!$B$5,0) -> 9 | F15: =ROUND(F10*(1+'Projection 12 mois'!$B$7)*'Projection 12 mois'!$B$4*'Projection 12 mois'!$B$5,0) -> 14 | G15: =ROUND(G10*(1+'Projection 12 mois'!$B$7)*'Projection 12 mois'!$B$4*'Projection 12 mois'!$B$5,0) -> 18 | H15: =ROUND(H10*(1+'Projection 12 mois'!$B$7)*'Projection 12 mois'!$B$4*'Projection 12 mois'!$B$5,0) -> 23 | I15: =ROUND(I10*(1+'Projection 12 mois'!$B$7)*'Projection 12 mois'!$B$4*'Projection 12 mois'!$B$5,0) -> 27 | ... M15: =ROUND(M10*(1+'Projection 12 mois'!$B$7)*'Projection 12 mois'!$B$4*'Projection 12 mois'!$B$5,0) -> 68 | N15: =SUM(B15:M15) -> 308
A16: Abonnés ESSENTIEL en fin de mois | B16: =B15 -> 2 | C16: =ROUND(B16*(1-'Projection 12 mois'!$B$6),0)+C15 -> 7 | D16: =ROUND(C16*(1-'Projection 12 mois'!$B$6),0)+D15 -> 14 | E16: =ROUND(D16*(1-'Projection 12 mois'!$B$6),0)+E15 -> 22 | F16: =ROUND(E16*(1-'Projection 12 mois'!$B$6),0)+F15 -> 35 | G16: =ROUND(F16*(1-'Projection 12 mois'!$B$6),0)+G15 -> 51 | H16: =ROUND(G16*(1-'Projection 12 mois'!$B$6),0)+H15 -> 71 | I16: =ROUND(H16*(1-'Projection 12 mois'!$B$6),0)+I15 -> 94 | J16: =ROUND(I16*(1-'Projection 12 mois'!$B$6),0)+J15 -> 125 | ... M16: =ROUND(L16*(1-'Projection 12 mois'!$B$6),0)+M15 -> 268 | N16: =M16 -> 268
A17: Nouveaux abonnés PRO | B17: =ROUND(B10*(1+'Projection 12 mois'!$B$7)*'Projection 12 mois'!$B$4*'Projection 12 mois'!$C$5,0) -> 2 | C17: =ROUND(C10*(1+'Projection 12 mois'!$B$7)*'Projection 12 mois'!$B$4*'Projection 12 mois'!$C$5,0) -> 4 | D17: =ROUND(D10*(1+'Projection 12 mois'!$B$7)*'Projection 12 mois'!$B$4*'Projection 12 mois'!$C$5,0) -> 5 | E17: =ROUND(E10*(1+'Projection 12 mois'!$B$7)*'Projection 12 mois'!$B$4*'Projection 12 mois'!$C$5,0) -> 7 | F17: =ROUND(F10*(1+'Projection 12 mois'!$B$7)*'Projection 12 mois'!$B$4*'Projection 12 mois'!$C$5,0) -> 11 | G17: =ROUND(G10*(1+'Projection 12 mois'!$B$7)*'Projection 12 mois'!$B$4*'Projection 12 mois'!$C$5,0) -> 14 | H17: =ROUND(H10*(1+'Projection 12 mois'!$B$7)*'Projection 12 mois'!$B$4*'Projection 12 mois'!$C$5,0) -> 18 | I17: =ROUND(I10*(1+'Projection 12 mois'!$B$7)*'Projection 12 mois'!$B$4*'Projection 12 mois'!$C$5,0) -> 22 | ... M17: =ROUND(M10*(1+'Projection 12 mois'!$B$7)*'Projection 12 mois'!$B$4*'Projection 12 mois'!$C$5,0) -> 54 | N17: =SUM(B17:M17) -> 245
A18: Abonnés PRO en fin de mois | B18: =B17 -> 2 | C18: =ROUND(B18*(1-'Projection 12 mois'!$B$6),0)+C17 -> 6 | D18: =ROUND(C18*(1-'Projection 12 mois'!$B$6),0)+D17 -> 11 | E18: =ROUND(D18*(1-'Projection 12 mois'!$B$6),0)+E17 -> 17 | F18: =ROUND(E18*(1-'Projection 12 mois'!$B$6),0)+F17 -> 27 | G18: =ROUND(F18*(1-'Projection 12 mois'!$B$6),0)+G17 -> 40 | H18: =ROUND(G18*(1-'Projection 12 mois'!$B$6),0)+H17 -> 56 | I18: =ROUND(H18*(1-'Projection 12 mois'!$B$6),0)+I17 -> 75 | J18: =ROUND(I18*(1-'Projection 12 mois'!$B$6),0)+J17 -> 100 | ... M18: =ROUND(L18*(1-'Projection 12 mois'!$B$6),0)+M17 -> 213 | N18: =M18 -> 213
A19: Nouveaux abonnés ULTRA | B19: =ROUND(B10*(1+'Projection 12 mois'!$B$7)*'Projection 12 mois'!$B$4*'Projection 12 mois'!$D$5,0) -> 0 | C19: =ROUND(C10*(1+'Projection 12 mois'!$B$7)*'Projection 12 mois'!$B$4*'Projection 12 mois'!$D$5,0) -> 1 | D19: =ROUND(D10*(1+'Projection 12 mois'!$B$7)*'Projection 12 mois'!$B$4*'Projection 12 mois'!$D$5,0) -> 1 | E19: =ROUND(E10*(1+'Projection 12 mois'!$B$7)*'Projection 12 mois'!$B$4*'Projection 12 mois'!$D$5,0) -> 2 | F19: =ROUND(F10*(1+'Projection 12 mois'!$B$7)*'Projection 12 mois'!$B$4*'Projection 12 mois'!$D$5,0) -> 3 | G19: =ROUND(G10*(1+'Projection 12 mois'!$B$7)*'Projection 12 mois'!$B$4*'Projection 12 mois'!$D$5,0) -> 4 | H19: =ROUND(H10*(1+'Projection 12 mois'!$B$7)*'Projection 12 mois'!$B$4*'Projection 12 mois'!$D$5,0) -> 5 | I19: =ROUND(I10*(1+'Projection 12 mois'!$B$7)*'Projection 12 mois'!$B$4*'Projection 12 mois'!$D$5,0) -> 5 | ... M19: =ROUND(M10*(1+'Projection 12 mois'!$B$7)*'Projection 12 mois'!$B$4*'Projection 12 mois'!$D$5,0) -> 14 | N19: =SUM(B19:M19) -> 62
A20: Abonnés ULTRA en fin de mois | B20: =B19 -> 0 | C20: =ROUND(B20*(1-'Projection 12 mois'!$B$6),0)+C19 -> 1 | D20: =ROUND(C20*(1-'Projection 12 mois'!$B$6),0)+D19 -> 2 | E20: =ROUND(D20*(1-'Projection 12 mois'!$B$6),0)+E19 -> 4 | F20: =ROUND(E20*(1-'Projection 12 mois'!$B$6),0)+F19 -> 7 | G20: =ROUND(F20*(1-'Projection 12 mois'!$B$6),0)+G19 -> 11 | H20: =ROUND(G20*(1-'Projection 12 mois'!$B$6),0)+H19 -> 15 | I20: =ROUND(H20*(1-'Projection 12 mois'!$B$6),0)+I19 -> 19 | J20: =ROUND(I20*(1-'Projection 12 mois'!$B$6),0)+J19 -> 25 | ... M20: =ROUND(L20*(1-'Projection 12 mois'!$B$6),0)+M19 -> 54 | N20: =M20 -> 54
A21: Total abonnés payants | B21: =B16+B18+B20 -> 4 | C21: =C16+C18+C20 -> 14 | D21: =D16+D18+D20 -> 27 | E21: =E16+E18+E20 -> 43 | F21: =F16+F18+F20 -> 69 | G21: =G16+G18+G20 -> 102 | H21: =H16+H18+H20 -> 142 | I21: =I16+I18+I20 -> 188 | ... M21: =M16+M18+M20 -> 535 | N21: =M21 -> 535
A22: Revenu abonnements | B22: =B16*Abonnements!$C$5+B18*Abonnements!$D$5+B20*Abonnements!$E$5 -> 99.96 | C22: =C16*Abonnements!$C$5+C18*Abonnements!$D$5+C20*Abonnements!$E$5 -> 419.86 | D22: =D16*Abonnements!$C$5+D18*Abonnements!$D$5+D20*Abonnements!$E$5 -> 809.73 | E22: =E16*Abonnements!$C$5+E18*Abonnements!$D$5+E20*Abonnements!$E$5 -> 1349.57 | F22: =F16*Abonnements!$C$5+F18*Abonnements!$D$5+F20*Abonnements!$E$5 -> 2209.31 | G22: =G16*Abonnements!$C$5+G18*Abonnements!$D$5+G20*Abonnements!$E$5 -> 3318.98 | H22: =H16*Abonnements!$C$5+H18*Abonnements!$D$5+H20*Abonnements!$E$5 -> 4598.58 | I22: =I16*Abonnements!$C$5+I18*Abonnements!$D$5+I20*Abonnements!$E$5 -> 6028.12 | ... M22: =M16*Abonnements!$C$5+M18*Abonnements!$D$5+M20*Abonnements!$E$5 -> 17144.65 | N22: =SUM(B22:M22) -> 67888.79
A23: Coût API (ElevenLabs, Gemini, OpenAI, Claude) | B23: =B16*Abonnements!$C$13+B18*Abonnements!$D$13+B20*Abonnements!$E$13 -> 57.93131 | C23: =C16*Abonnements!$C$13+C18*Abonnements!$D$13+C20*Abonnements!$E$13 -> 248.65647 | D23: =D16*Abonnements!$C$13+D18*Abonnements!$D$13+D20*Abonnements!$E$13 -> 481.33834 | E23: =E16*Abonnements!$C$13+E18*Abonnements!$D$13+E20*Abonnements!$E$13 -> 804.85734 | F23: =F16*Abonnements!$C$13+F18*Abonnements!$D$13+F20*Abonnements!$E$13 -> 1319.1015 | G23: =G16*Abonnements!$C$13+G18*Abonnements!$D$13+G20*Abonnements!$E$13 -> 1982.1141 | H23: =H16*Abonnements!$C$13+H18*Abonnements!$D$13+H20*Abonnements!$E$13 -> 2745.0147 | I23: =I16*Abonnements!$C$13+I18*Abonnements!$D$13+I20*Abonnements!$E$13 -> 3594.8123 | ... M23: =M16*Abonnements!$C$13+M18*Abonnements!$D$13+M20*Abonnements!$E$13 -> 10225.253 | N23: =SUM(B23:M23) -> 40486.654
A24: Frais Stripe abonnements | B24: =B22*Hypothèses!$B$7+B21*Hypothèses!$B$8 -> 4.09884 | C24: =C22*Hypothèses!$B$7+C21*Hypothèses!$B$8 -> 16.37594 | D24: =D22*Hypothèses!$B$7+D21*Hypothèses!$B$8 -> 31.58217 | E24: =E22*Hypothèses!$B$7+E21*Hypothèses!$B$8 -> 52.03753 | F24: =F22*Hypothèses!$B$7+F21*Hypothèses!$B$8 -> 84.76999 | G24: =G22*Hypothèses!$B$7+G21*Hypothèses!$B$8 -> 126.85042 | H24: =H22*Hypothèses!$B$7+H21*Hypothèses!$B$8 -> 175.95882 | I24: =I22*Hypothèses!$B$7+I21*Hypothèses!$B$8 -> 231.21548 | ... M24: =M22*Hypothèses!$B$7+M21*Hypothèses!$B$8 -> 657.69485 | N24: =SUM(B24:M24) -> 2605.0749
A25: Marge brute abonnements | B25: =B22-B23-B24 -> 37.92985 | C25: =C22-C23-C24 -> 154.82759 | D25: =D22-D23-D24 -> 296.80949 | E25: =E22-E23-E24 -> 492.67513 | F25: =F22-F23-F24 -> 805.43851 | G25: =G22-G23-G24 -> 1210.0155 | H25: =H22-H23-H24 -> 1677.6065 | I25: =I22-I23-I24 -> 2202.0922 | ... M25: =M22-M23-M24 -> 6261.7026 | N25: =SUM(B25:M25) -> 24797.061
A27: REVENU TOTAL | B27: =B11+B22 -> 2844.96 | C27: =C11+C22 -> 5909.86 | D27: =D11+D22 -> 9044.73 | E27: =E11+E22 -> 12329.57 | F27: =F11+F22 -> 18679.31 | G27: =G11+G22 -> 25278.98 | H27: =H11+H22 -> 32048.58 | I27: =I11+I22 -> 38968.12 | ... M27: =M11+M22 -> 99494.65 | N27: =SUM(B27:M27) -> 441208.79
A28: MARGE BRUTE TOTALE | B28: =B13+B25 -> 1333.7749 | C28: =C13+C25 -> 2746.5176 | D28: =D13+D25 -> 4184.3445 | E28: =E13+E25 -> 5676.0551 | F28: =F13+F25 -> 8580.5085 | G28: =G13+G25 -> 11576.775 | H28: =H13+H25 -> 14636.056 | I28: =I13+I25 -> 17752.232 | ... M28: =M13+M25 -> 45137.053 | N28: =SUM(B28:M28) -> 201031.98
A29: Coûts fixes (Hypothèses §7) + salaire | B29: =Hypothèses!$C$83+Hypothèses!$C$84 -> 1113.0264 | C29: =Hypothèses!$C$83+Hypothèses!$C$84 -> 1113.0264 | D29: =Hypothèses!$C$83+Hypothèses!$C$84 -> 1113.0264 | E29: =Hypothèses!$C$83+Hypothèses!$C$84 -> 1113.0264 | F29: =Hypothèses!$C$83+Hypothèses!$C$84 -> 1113.0264 | G29: =Hypothèses!$C$83+Hypothèses!$C$84 -> 1113.0264 | H29: =Hypothèses!$C$83+Hypothèses!$C$84 -> 1113.0264 | I29: =Hypothèses!$C$83+Hypothèses!$C$84 -> 1113.0264 | ... M29: =Hypothèses!$C$83+Hypothèses!$C$84 -> 1113.0264 | N29: =SUM(B29:M29) -> 13356.317
A30: RÉSULTAT MENSUEL avant impôts | B30: =B28-B29 -> 220.74845 | C30: =C28-C29 -> 1633.4912 | D30: =D28-D29 -> 3071.3181 | E30: =E28-E29 -> 4563.0287 | F30: =F28-F29 -> 7467.4821 | G30: =G28-G29 -> 10463.749 | H30: =H28-H29 -> 13523.03 | I30: =I28-I29 -> 16639.206 | ... M30: =M28-M29 -> 44024.026 | N30: =SUM(B30:M30) -> 187675.66
A31: Trésorerie cumulée (hors achat du stock initial) | B31: =B30 -> 220.74845 | C31: =B31+C30 -> 1854.2396 | D31: =C31+D30 -> 4925.5577 | E31: =D31+E30 -> 9488.5865 | F31: =E31+F30 -> 16956.069 | G31: =F31+G30 -> 27419.818 | H31: =G31+H30 -> 40942.848 | I31: =H31+I30 -> 57582.054 | J31: =I31+J30 -> 80124.991 | ... M31: =L31+M30 -> 187675.66 | N31: =M31 -> 187675.66
A33: Indicateurs
A34: Premier mois rentable (résultat mensuel ≥ 0) | B34: =IFERROR(MATCH(TRUE,INDEX(B30:M30>=0,0),0),"> 12 mois") -> 1
A35: Ventes de lunettes par mois pour couvrir les coûts fixes (sans abonnement) | B35: =IF('Coût lunettes'!$B$32<=0,0,ROUNDUP((Hypothèses!$C$83+Hypothèses!$C$84)/'Coût lunettes'!$B$32,0)) -> 5
A36: Abonnés PRO nécessaires pour couvrir les coûts fixes (sans lunettes) | B36: =IF(Abonnements!$D$15<=0,0,ROUNDUP((Hypothèses!$C$83+Hypothèses!$C$84)/Abonnements!$D$15,0)) -> 87
A37: Stock initial à financer (palier choisi, CAD) | B37: =INDEX('Coût lunettes'!B26:E26,MATCH(Hypothèses!$B$9,'Coût lunettes'!B5:E5,0)) -> 122570
A38: Revenu annuel récurrent (ARR) en fin de mois 12 | B38: =M22*12 -> 205735.8
